Workbook

Sheet Лист4
A1: № | B1: Наименование Проекта | C1: Дата решение Правления/СД | D1: Регион | E1: Застройщик | F1: БИН Застройщика | G1: Уполномоченная компания | H1: БИН Уполномоченной компании | I1: Стоимость, тенге | J1: Площадь, кв.м по Проекту | K1: Площадь квартир, кв.м по Проекту | L1: Себестоимость тыс.тенге/1 м2 | M1: Цена реал. тыс.тенге/1 м2 | N1: Дата заключения договора о предоставлении гарантии | O1: Количество квартир по Проекту | P1: Количество квартир по факту (после ввода)* | Q1: Этажность | R1: Дата начала строительства | S1: Дата завершения | T1: Дата пролонгации 1 | U1: Дата пролонгации 2 | V1: Дата пролонгации 3 | W1: Дата завершения 2 | X1: Гарантийный взнос, тенге | Y1: № ДПГ | Z1: Стоимость увеличение/уменьшение обзятельств | AA1: Исполнитель | AB1: Балл Застройщика | AC1: Кол-во продлении | AD1: Кол-во модерации | AE1: Номер в SB | AF1: Наличие "Зеленого сертификатв" | AG1: Статус
A2: 1 | B2: ЖК "Миллениум парк", пятно 2, 14 блок | C2: 42870 | D2: г. Астана | E2: ТОО "BAZIS-A Corp." | F2: 960340000376 | G2: ТОО "Аллея тысячелетия-2" | H2: 160340010693 | I2: 2516814000 | J2: 14000 | N2: 42873 | O2: 178 | P2: 178 | Q2: 24 | R2: 42513 | S2: 43519 | W2: 43154 | X2: 50336280 | Y2: ДПГ-17-01-001-02/001 | AB2: 100 | AG2: Завершенные
A3: 2 | B3: ЖК "Легенда", 1 очередь (пятна 1-6) | C3: 42968 | D3: г. Алматы | E3: ТОО "BAZIS-A Corp." | F3: 960340000376 | G3: ТОО "KAT-Construction" | H3: 160640015734 | I3: 6866978080 | J3: 35371.3 | N3: 43000 | O3: 400 | P3: 396 | Q3: 14-16 | R3: 42895 | S3: 43474 | W3: 43454 | X3: 137339562 | Y3: ДПГ-17-02-001/002 | AB3: 100 | AG3: Завершенные
A4: 3 | B4: ЖК Алтын Ұя | C4: 43090 | D4: г. Астана | E4: ТОО "Comfort Development KZ" | F4: 210940032945 | G4: ТОО "AKAN Engineering" | H4: 140540020406 | I4: 1576632159 | J4: 13084 | N4: 43122 | O4: 148 | P4: 167 | Q4: 10 | R4: 42765 | S4: 43339 | W4: 43339 | X4: 18956603 | Y4: ДПГ-17-01-002/003 | AB4: 67 | AG4: Завершенные
A5: 4 | B5: МЖК Легенда, 2 очередь, ПАРКИНГ | C5: 43132 | D5: г. Алматы | E5: ТОО "BAZIS-A Corp." | F5: 960340000376 | G5: ТОО "KAT-Construction" | H5: 160640015734 | I5: 1348115202 | J5: 8303.1 | N5: 43146 | O5: 233 | P5: 233 | Q5: 1 | R5: 43005 | S5: 43461 | W5: 43454 | X5: 24756844 | Y5: доп.согл. №1 к ДПГ-17-02-001/002 | AB5: 100 | AG5: Завершенные
A6: 5 | B6: МЖК Alma City, 1 очередь | C6: 43193 | D6: г. Алматы | E6: ТОО "Qazaq Stroy" | F6: 050540016141 | G6: ТОО "Елимай-Invest" | H6: 160640016168 | I6: 1543068030 | J6: 26577.5 | N6: 43214 | O6: 300 | P6: 360 | Q6: 5 | R6: 43161 | S6: 43526 | W6: 43482 | X6: 28414166 | Y6: ДПГ-18-02-005/006 | AB6: 91 | AG6: Завершенные
A7: 6 | B7: ЖК на Гагарина 1 | C7: 43206 | D7: г. Уральск | E7: ТОО "Караванный путь" | F7: 030840007596 | G7: ТОО "Stroy Baiterek" | H7: 170740034528 | I7: 1279348120 | J7: 7546.7 | N7: 43218 | O7: 126 | P7: 126 | Q7: 9 | R7: 42964 | S7: 43512 | W7: 43477 | X7: 15796882 | Y7: ДПГ-18-07-006/007 | AB7: 64 | AG7: Завершенные
A8: 7 | B8: МЖК Alma City, 2 очередь | C8: 43325 | D8: г. Алматы | E8: ТОО "Qazaq Stroy" | F8: 050540016141 | G8: ТОО "Елимай-Invest" | H8: 160640016168 | I8: 1543068032 | J8: 26577.5 | N8: 43326 | O8: 300 | P8: 360 | Q8: 5 | R8: 43161 | S8: 43526 | W8: 43482 | X8: 30861361 | Y8: доп.согл. 1 к ДПГ-18-02-005/006 | AB8: 90 | AG8: Завершенные
A9: 8 | B9: МЖК Легенда, 3 очередь, пятна 7, 8, | C9: 43159 | D9: г. Алматы | E9: ТОО "BAZIS-A Corp." | F9: 960340000376 | G9: ТОО "KAT-Construction" | H9: 160640015734 | I9: 2198326780 | J9: 12592.6 | N9: 43175 | O9: 134 | P9: 134 | Q9: 14-15 | R9: 43116 | S9: 43540 | T9: 43632 | W9: 43633 | X9: 43145556 | Y9: доп.согл. №2 к ДПГ-17-02-001/002 | AB9: 100 | AG9: Завершенные
A10: 9 | B10: ЖК SUNRISE | C10: 43325 | D10: г. Астана | E10: ТОО "Милан-Астана" | F10: 110540015593 | G10: ТОО "Тенгри Хаус Астана" | H10: 130340016121 | I10: 7519312044 | J10: 29141.3 | N10: 43341 | O10: 458 | P10: 569 | Q10: 8-9 | R10: 43230 | S10: 43718 | W10: 43703 | X10: 141232414 | Y10: доп.согл. №1 к ДПГ-18-01-008/009 | AB10: 78 | AG10: Завершенные
A11: 10 | B11: ЖК Nova City | C11: 43390 | D11: г. Астана | E11: ТОО "Милан-Астана" | F11: 110540015593 | G11: ТОО "Камал Центр Астана" | H11: 170540018975 | I11: 6690458969 | J11: 28555.6 | N11: 43398 | O11: 467 | P11: 467 | Q11: 9 | R11: 43296 | S11: 43799 | T11: 43799 | W11: 43784 | X11: 127426511 | Y11: ДПГ-18-01-008/011 | AB11: 78 | AG11: Завершенные
A12: 11 | B12: ЖК Alma City-2 | C12: 43454 | D12: г. Алматы | E12: ТОО "Qazaq Stroy" | F12: 050540016141 | G12: ТОО "Нұр City Investment" | H12: 181140015247 | I12: 7891739810 | J12: 66742.5 | N12: 43458 | O12: 984 | P12: 1059 | Q12: 9 | R12: 43431 | S12: 43795 | W12: 43788 | X12: 141881753 | Y12: ДПГ-18-02-005/012 | AB12: 90 | AG12: Завершенные
A13: 12 | B13: ЖК Биік Шаңырақ | C13: 43147 | D13: г. Астана | E13: ТОО "НАЕК" | F13: 940140001482 | G13: ТОО "Биік Шаңырақ" | H13: 140740007872 | I13: 2146903508 | J13: 17848.8 | N13: 43162 | O13: 260 | P13: 276 | Q13: 14 | R13: 43160 | S13: 29.02.2019 | T13: 43616 | U13: 43708 | V13: 43890 | W13: 43803 | X13: 36796147 | Y13: ДПГ-18-01-003/004 | Z13: 1302438420 | AB13: 77 | AG13: Завершенные
A14: 13 | B14: ЖК Бахыт, 1 очередь | C14: 43166 | D14: г. Шымкент | E14: ТОО "Оңтүстік құрылыс Сервис" | F14: 010340004024 | G14: ТОО "Композит-7" | H14: 050640012251 | I14: 2458898850 | J14: 16417.7 | N14: 43194 | O14: 104 | P14: 104 | Q14: 9 | R14: 43160 | S14: 30.04.2019 | T14: 43676 | U14: 43768 | V14: 43860 | W14: 43824 | X14: 46976477 | Y14: ДПГ-18-13-004/005 | Z14: 2458898850 | AB14: 64 | AG14: Завершенные
A15: 14 | B15: МЖК Легенда, 5 очередь, пятна 9, 10 | C15: 43313 | D15: г. Алматы | E15: ТОО "BAZIS-A Corp." | F15: 960340000376 | G15: ТОО "KAT-Construction" | H15: 160640015734 | I15: 2502632570 | J15: 12341.8 | N15: 43315 | O15: 94 | P15: 94 | Q15: 14-15 | R15: 43280 | S15: 43859 | W15: 43822 | X15: 48468231 | Y15: доп.согл. №3 к ДПГ-17-02-001/002 | AB15: 83 | AG15: Завершенные
A16: 15 | B16: ЖК Триумфальная арка-2 | C16: 43334 | D16: г. Астана | E16: ТОО "Ңұр Астана Құрылыс" | F16: 060140000846 | G16: ТОО "Мангилик Ел Курылыс" | H16: 170240033531 | I16: 5341879260 | J16: 23920.8 | N16: 43385 | O16: 142 | P16: 136 | Q16: 4,7,9 | R16: 43269 | S16: 44000 | W16: 43977 | X16: 93091230 | Y16: ДПГ-18-01-009/010 | AB16: 67 | AG16: Завершенные
A17: 16 | B17: МЖК Багыстан, 1-я очередь, 2-очередь, 1, 3 позиции | C17: 43210 | D17: г. Астана | E17: ТОО "Шар Курылыс" | F17: 980740001878 | G17: ТОО "Бағыстан" | H17: 161140023096 | I17: 6541727260 | J17: 41688.6 | N17: 43216 | O17: 324 | P17: 324 | Q17: 5,7,9 | R17: 42921 | S17: 1 позиция - 10.08.2021г.; 3 позиция - 20.10.2021г. | T17: 44134 | U17: 44226 | V17: 44316 | W17: 44489 | X17: 110832077 | Y17: ДПГ-18-01-007/008 | AB17: 83 | AG17: Завершенные
A18: 17 | B18: МЖК Багыстан, 3-я очередь, 7 позиция | C18: 43286 | D18: г. Астана | E18: ТОО "Шар Курылыс" | F18: 980740001878 | G18: ТОО "Бағыстан" | H18: 161140023096 | I18: 3024902930 | J18: 13362.1 | N18: 43291 | O18: 152 | P18: 152 | Q18: 5,7,9 | R18: 43040 | S18: 20.10.2021 | T18: 44134 | U18: 44226 | V18: 44316 | W18: 44489 | X18: 56590879 | Y18: доп.согл.№1 к ДПГ-18-01-007/008 | AB18: 83 | AG18: Завершенные
A19: 18 | B19: МЖК Багыстан, 4-я очередь, 11 позиция | C19: 43325 | D19: г. Астана | E19: ТОО "Шар Курылыс" | F19: 980740001878 | G19: ТОО "Бағыстан" | H19: 161140023096 | I19: 3014702450 | J19: 13367.2 | N19: 43336 | O19: 152 | P19: 152 | Q19: 5,7,9 | R19: 43266 | S19: 30.07.2020 | T19: 44134 | U19: 44226 | V19: 44316 | W19: 44489 | X19: 59088033 | Y19: доп.согл.№3 к ДПГ-18-01-007/008 | AB19: 83 | AG19: Завершенные
A20: 19 | B20: МЖК Sezim Qala, 1 очередь | C20: 43515 | D20: г. Астана | E20: ТОО "Милан-Астана" | F20: 110540015593 | G20: ТОО "Туран Сити" | H20: 170340033307 | I20: 4220953472 | J20: 21443 | N20: 43518 | O20: 277 | P20: 266 | Q20: 9.12 | R20: 43441 | S20: 44142 | W20: 43824 | X20: 79630069 | Y20: доп.согл.№1 к ДПГ-19-01-008/015 | AB20: 78 | AG20: Завершенные
A21: 20 | B21: ЖК Легенда, 4 очередь (пятна 11, 12) | C21: 43523 | D21: г. Алматы | E21: ТОО "BAZIS-A Corp." | F21: 960340000376 | G21: ТОО "KAT-Construction" | H21: 160640015734 | I21: 1957311630 | J21: 12418.3 | N21: 43543 | O21: 142 | P21: 142 | Q21: 14-15 | R21: 43481 | S21: 43815 | T21: 43906 | W21: 43866 | X21: 37257013 | Y21: доп.согл.№7 к ДПГ-17-02-001/002 | AB21: 83 | AG21: Завершенные
A22: 21 | B22: МЖК Nova City, 19 очередь | C22: 43501 | D22: г. Астана | E22: ТОО "Милан-Астана" | F22: 110540015593 | G22: ТОО "Esil Town" | H22: 181140019271 | I22: 2227028801 | J22: 8855.87 | N22: 43511 | O22: 150 | P22: 150 | Q22: 9 | R22: 43521 | S22: 43946 | W22: 43938 | X22: 43834498 | Y22: ДПГ-19-01-001/014 | AB22: 78 | AG22: Завершенные
A23: 22 | B23: МЖК Alma City, 3-оч. 1-й пуск.комплекс | C23: 43726 | D23: г. Алматы | E23: ТОО "Qazaq Stroy" | F23: 050540016141 | G23: ТОО "ЫРЫСТЫ 46/2" | H23: 190340022583 | I23: 6600809540 | J23: 64684.2 | N23: 43728 | O23: 1008 | P23: 1118 | Q23: 9 | R23: 43711 | S23: 44257 | W23: 43965 | X23: 132016191 | Y23: ДПГ-19-02-005/024 | AB23: 81 | AG23: Завершенные
A24: 23 | B24: МЖК Амстердам, пятна 4,5,6,7,15.1 | C24: 43482 | D24: г. Астана | E24: ТОО "BAZIS-A Corp." | F24: 960340000376 | G24: ТОО "Amsterdam City" | H24: 180640022394 | I24: 3484165830 | J24: 20748.3 | N24: 43518 | O24: 110 | P24: 100 | Q24: 9-10 | R24: 43357 | S24: 44042 | W24: 44039 | X24: 68156153 | Y24: ДПГ-19-01-001/013 | AB24: 83 | AG24: Завершенные
A25: 24 | B25: ЖК Nova City 16 очередь | C25: 43634 | D25: г. Астана | E25: ТОО "Милан-Астана" | F25: 110540015593 | G25: ТОО "NC16" | H25: 181240011486 | I25: 4429569296 | J25: 20614.56 | N25: 43647 | O25: 242 | P25: 242 | Q25: 9 | R25: 43588 | S25: 44107 | W25: 44049 | X25: 86509774 | Y25: ДПГ-19-01-008/016 | AB25: 91 | AG25: Завершенные
A26: 25 | B26: МЖК Парасат, пятно 1,2 | C26: 43783 | D26: г. Алматы | E26: ТОО "SHEBERBUILD" | F26: 070240017648 | G26: ТОО "SHEBERGOOD" | H26: 070240017648 | I26: 1733779999 | J26: 7731.36 | N26: 43796 | O26: 143 | P26: 143 | Q26: 9 | R26: 43760 | S26: 43973 | T26: 44065 | W26: 44064 | X26: 30929009 | Y26: ДПГ-19-02-013/030 | AB26: 70 | AG26: Завершенные
A27: 26 | B27: ЖК Премьера | C27: 43676 | D27: г. Шымкент | E27: ТОО "Оңтүстік құрылыс Сервис" | F27: 010340004024 | G27: ТОО "Dostyq Invest Group" | H27: 190140008530 | I27: 1355115090 | J27: 8903.44 | N27: 43697 | O27: 80 | P27: 80 | Q27: 5 | R27: 43635 | S27: 43970 | T27: 44062 | U27: 44123 | W27: 44068 | X27: 24228296 | Y27: ДПГ-19-13-004/020 | AB27: 61 | AG27: Завершенные
A28: 27 | B28: МЖК Nova City, 22 очередь | C28: 43676 | D28: г. Астана | E28: ТОО "Милан-Астана" | F28: 110540015593 | G28: ТОО "NC 22" | H28: 190340029392 | I28: 2453517883 | J28: 8855.87 | N28: 43689 | O28: 150 | P28: 150 | Q28: 9 | R28: 43626 | S28: 44114 | W28: 44112 | X28: 48045915 | Y28: ДПГ-19-01-008/021 | AB28: 91 | AG28: Завершенные
A29: 28 | B29: ЖК ASQAT | C29: 43665 | D29: г. Астана | E29: ТОО "АсТи-Строй" | F29: 030740000258 | G29: ТОО "ASTI GROUP" | H29: 071240012104 | I29: 3019265161 | J29: 15344.61 | N29: 43677 | O29: 108 | P29: 108 | Q29: 7 | R29: 43633 | S29: 44180 | W29: 44165 | X29: 50272872 | Y29: ДПГ-19-01-010/018 | AB29: 91 | AG29: Завершенные
A30: 29 | B30: МЖК Argento, пятно 3 | C30: 44081 | D30: г. Астана | E30: ТОО "BAZIS-A Corp." | F30: 960340000376 | G30: ТОО "Строй Билдинг Астана" | H30: 170840009898 | I30: 1136489476 | J30: 7918.13 | N30: 43670 | O30: 85 | P30: 85 | Q30: 18 | R30: 43956 | S30: 44413 | W30: 44398 | X30: 19307570 | Y30: ДПГ-19-01-001/017 | AB30: 84 | AG30: Завершенные
A31: 30 | B31: МЖК 12 месяцев (на Макатаева), 1-очередь | C31: 43726 | D31: г. Алматы | E31: ТОО "Qazaq Stroy" | F31: 050540016141 | G31: ТОО "Макатаева 127" | H31: 190340022513 | I31: 5130621336 | J31: 36276.5 | N31: 43728 | O31: 432 | P31: 468 | Q31: 12 | R31: 43712 | S31: 44188 | W31: 44188 | X31: 102612427 | Y31: ДПГ-19-02-005/025 | AB31: 81 | AG31: Завершенные
A32: 31 | B32: ЖК Argento пятно 4, Наружные сети | C32: 43643 | D32: г. Астана | E32: ТОО "BAZIS-A Corp." | F32: 960340000376 | G32: ТОО "Строй Билдинг Астана" | H32: 170840009898 | I32: 2161436079 | J32: 12298.3 | N32: 43670 | O32: 100 | P32: 100 | Q32: 21 | R32: 43614 | S32: 44103 | T32: 44194 | W32: 44193 | X32: 41160642 | Y32: ДПГ-19-01-001/017 | AB32: 78 | AG32: Завершенные
A33: 32 | B33: ЖК Амстердам, пятна 1,2,3 | C33: 43777 | D33: г. Астана | E33: ТОО "BAZIS-A Corp." | F33: 960340000376 | G33: ТОО "Amsterdam City" | H33: 180640022394 | I33: 2176943630 | J33: 11705.1 | N33: 43783 | O33: 82 | P33: 82 | Q33: 9.1 | R33: 43712 | S33: 44193 | W33: 44193 | X33: 42801333 | Y33: доп.согл.№ 1 к ДПГ-19-01-001/013 | AB33: 84 | AG33: Завершенные
A34: 33 | B34: ЖК Бахыт, 2 очередь | C34: 43628 | D34: г. Шымкент | E34: ТОО "Оңтүстік құрылыс Сервис" | F34: 010340004024 | G34: ТОО "Композит-7" | H34: 050640012251 | I34: 4853681279 | J34: 27937.7 | N34: 43629 | O34: 168 | P34: 168 | Q34: 9 | R34: 43588 | S34: 44258 | T34: 44350 | W34: 44247 | X34: 77180276 | Y34: доп.согл. №3 к ДПГ-18-13-004/005 | Z34: 3859013800 | AB34: 61 | AG34: Завершенные
A35: 34 | B35: ЖК Ак Дидар, пятна 9-13 | C35: 43692 | D35: г. Астана | E35: ТОО "BAZIS-A Corp." | F35: 960340000376 | G35: ТОО "Ак Дидар-2" | H35: 170840012253 | I35: 2415410355 | J35: 16376.6 | N35: 43711 | O35: 276 | P35: 248 | Q35: 9 | R35: 43613 | S35: 44255 | T35: 44344 | W35: 44284 | X35: 48308207 | Y35: ДПГ-19-01-001/022 | AB35: 78 | AG35: Завершенные
B36: Увеличение стоимости ЖК "Ак Дидар", (пятна 9-13) | C36: 43875 | D36: г. Астана | E36: ТОО "BAZIS-A Corp." | F36: 960340000376 | G36: ТОО "Ак Дидар-2" | H36: 170840012253 | I36: 698876654 | J36: 4954 | N36: 43880 | O36: 0 | P36: 0 | Q36: - | R36: 43613 | S36: 44255 | T36: 44344 | W36: 44284 | X36: 13977533 | Y36: доп.согл. №1 к ДПГ-19-01-001/022 | AB36: 78 | AG36: Завершенные
A37: 35 | B37: ЖК Aspan City | C37: 43665 | D37: Алматинская обл. | E37: ТОО "Exclusive Construction (Эксклюзив Констракшн)" | F37: 051040013647 | G37: ТОО "Aspan City 2" | H37: 181040020140 | I37: 4672680111 | J37: 23277.66 | N37: 43679 | O37: 288 | P37: 267 | Q37: 12 | R37: 43651 | S37: 44058 | T37: 44150 | U37: 44242 | V37: 44331 | W37: 44321 | X37: 93453602 | Y37: ДПГ-19-02-011/019 | AB37: 73 | AG37: Завершенные
A38: 36 | B38: МЖК Бестерек, пятно 1 | C38: 43726 | D38: г. Астана | E38: ТОО "Милан-Астана" | F38: 110540015593 | G38: ТОО "BI-Village Deluxe" | H38: 070340010951 | I38: 6019547133 | J38: 26723.09 | N38: 43735 | O38: 307 | P38: 307 | Q38: 8 | R38: 43662 | S38: 44363 | W38: 44361 | X38: 119220603 | Y38: ДПГ-19-01-008/023 | AB38: 91 | AG38: Завершенные
A39: 37 | B39: МЖК Sezim Qala, 4 очередь | C39: 43791 | D39: г. Астана | E39: ТОО "Милан-Астана" | F39: 110540015593 | G39: ТОО "Туран Сити" | H39: 170340033307 | I39: 3663548205 | J39: 19815.5 | N39: 43791 | O39: 278 | P39: 278 | Q39: 2, 9, 12 | R39: 43759 | S39: 44393 | W39: 44363 | X39: 72343291 | Y39: доп.согл.№3 к ДПГ-19-01-008/015 | AB39: 91 | AG39: Завершенные
A40: 38 | B40: ЖК Sezim Qala, 7 очередь | C40: 43748 | D40: г. Астана | E40: ТОО "Милан-Астана" | F40: 110540015593 | G40: ТОО "Туран Сити" | H40: 170340033307 | I40: 5814608330 | J40: 32516 | N40: 43749 | O40: 408 | P40: 408 | Q40: 22 | R40: 43704 | S40: 44496 | W40: 44347 | X40: 114777807 | Y40: доп.согл.№2 к ДПГ-19-01-008/015 | AB40: 91 | AG40: Завершенные
...

Sheet Действующие
D1: Гарантийный случай
D2: Консервация
D3: ЧС
B4: Действующие проекты | D4: Акты ввода на регистрации
A6: № | B6: Наименование Проекта | C6: Дата решение Правления/СД | D6: Регион | E6: Застройщик | F6: БИН Застройщика | G6: Уполномоченная компания | H6: БИН Уполномоченной компании | I6: Стоимость, тенге | J6: Площадь, кв.м по Проекту | K6: Площадь квартир, кв.м по Проекту | L6: Площадь коммерческих помещений, кв.м. | M6: Себестоимость тыс.тенге/1 м2 | N6: Цена реал. тыс.тенге/1 м2 | O6: Дата заключения договора о предоставлении гарантии | P6: Количество квартир по Проекту | Q6: Количество квартир по факту (после ввода)* | R6: Этажность | S6: Дата начала строительства | T6: Дата завершения | U6: Дата пролонгации 1 | V6: Дата пролонгации 2 | W6: Дата пролонгации 3 | X6: Дата завершения 2/Дата по АПОЭ | Y6: Гарантийный взнос, тенге | Z6: № ДПГ | AA6: Итоговая стоимость с учетом снижения обязательств | AB6: Исполнитель | AC6: Куратор | AD6: Балл Застройщика | AE6: Кол-во продлении | AF6: Кол-во модерации | AG6: Номер в SB | AH6: Наличие "Зеленого сертификатв" | AI6: Регион Кол-во | AJ6: Регион Ст-ть | AK6: Год Кол-во | AL6: Год Ст-ть | AM6: Статус
A7: 1 | B7: МЖК JM CITY Дом Парк | C7: 44497 | D7: г. Астана | E7: ТОО "Каспий Құрылыс ЛТД" | F7: 060740001628 | G7: ТОО "Garant Investment" | H7: 170440014681 | I7: 14682663880 | J7: 52536.8 | K7: 35232.12 | L7: 3356.68 | M7: 279.474 | N7: 385 | O7: 44518 | P7: 390 | R7: 12.16 | S7: 44258 | T7: 45294 | U7: 45385 | V7: 45476 | W7: 45568 | X7: 03.10.2024 Гарантийный случай | Y7: 131346323 | Z7: ДПГ-21-01-039/098 | AB7: Баркинхоев А.М. | AC7: Алимжанова Д.К. | AD7: 100 | AE7: 3 | AI7: г. Астана | AJ7: г. Астана | AK7: =CONCATENATE(YEAR(O7)," год") -> 2021 год | AL7: =CONCATENATE(YEAR(O7)," год") -> 2021 год | AM7: 1
A8: 2 | B8: МЖК Алия, 2 очередь | C8: 44504 | D8: г. Актобе | E8: ТОО "Сартай Энерго Сервис" | F8: 070240022179 | G8: ТОО "K7 Engineering" | H8: 191040002530 | I8: 7324207552 | J8: =84002.5-35757.72 -> 48244.78 | K8: 35637.8 | M8: 154.4 | N8: 200 | O8: 44523 | P8: =1040-480 -> 560 | R8: 5 | S8: 45026 | T8: 45848 | X8: 45848 | Y8: 116526220 | Z8: ДПГ-21-04-021/096 | AB8: Аяпова Г.Н. | AC8: Жусанова Т.А. | AD8: 80 | AE8: 0 | AI8: г. Актобе | AJ8: г. Актобе | AK8: =CONCATENATE(YEAR(O8)," год") -> 2021 год | AL8: =CONCATENATE(YEAR(O8)," год") -> 2021 год | AM8: 1
A9: 3 | B9: МЖК Kerim | C9: 44749 | D9: г. Астана | E9: ТОО "Актау Коркем Курылыс" | F9: 180440021488 | G9: ТОО "ОрдаСтройИнжиниринг" | H9: 110940007041 | I9: 5361772296 | J9: 34095.27 | K9: 22518.75 | L9: 3377.59 | M9: 157.2 | N9: 320 | O9: 44783 | P9: 294 | R9: 8 | S9: 44636 | T9: 45185 | U9: 45276 | V9: 45367 | X9: 16.03.2024 Акт на регистрации | Y9: 22318259 | Z9: ДПГ-22-01-054/117 | AB9: Баркинхоев А.М. | AC9: Алимжанова Д.К. | AD9: 93 | AE9: 2 | AI9: г. Астана | AJ9: г. Астана | AK9: =CONCATENATE(YEAR(O9)," год") -> 2022 год | AL9: =CONCATENATE(YEAR(O9)," год") -> 2022 год | AM9: 1
A10: 4 | B10: МЖК SPARKLE DIAMOND | C10: 44777 | D10: г. Усть-Каменогорск | E10: ТОО "ВВД-Құрылыс" | F10: 060240025805 | G10: ТОО "SPARKLE DIAMOND" | H10: 220540001566 | I10: 3704798634 | J10: 10948.36 | K10: 7609.46 | L10: 1455.3 | M10: 338.388 | N10: 445.5 | O10: 44800 | P10: 93 | R10: 5 | S10: 44691 | T10: 45422 | U10: 45514 | X10: 10.08.2024 Гарантийный случай | Y10: 33068755 | Z10: ДПГ-22-16-055/120 | AB10: Баркинхоев А.М. | AC10: Алимжанова Д.К. | AD10: 84 | AE10: 1 | AG10: 273 | AI10: г. Усть-Каменогорск | AJ10: г. Усть-Каменогорск | AK10: =CONCATENATE(YEAR(O10)," год") -> 2022 год | AL10: =CONCATENATE(YEAR(O10)," год") -> 2022 год | AM10: 1
A11: 5 | B11: МЖК Cемья, 2 очередь | C11: 44796 | D11: г. Костанай | E11: ТОО "Trans Service Company AST" | F11: 080740001641 | G11: ТОО "ИННОВАЦИЯ ПЛЮС" | H11: 220240017482 | I11: 881590818 | J11: 6145.2 | K11: 2059.6 | M11: 216.9 | N11: 257.5 | O11: 44823 | P11: 68 | R11: 4 | S11: 44679 | T11: 45258 | U11: 45350 | V11: 28.05.2024/ продлен по ЧС до 12.07.2024 | X11: 12.07.2024 Акт на регистрации | Y11: 15542092 | Z11: ДПГ-22-10-056/121 | AB11: Кенесов М.Г. | AC11: Арыстанбекова А.И. | AD11: 81 | AE11: 2 | AG11: 246 | AI11: г. Костанай | AJ11: г. Костанай | AK11: =CONCATENATE(YEAR(O11)," год") -> 2022 год | AL11: =CONCATENATE(YEAR(O11)," год") -> 2022 год | AM11: 1
A12: 6 | B12: МЖК Яссауи | C12: 44939 | D12: г. Астана | E12: ТОО "Айзия KZ" | F12: 121240010070 | G12: ТОО "Astana oil trade" | H12: 100740015241 | I12: 6548335303 | J12: 30385.95 | K12: 17064.44 | L12: 1435.64 | M12: 304.773 | N12: 393.237 | O12: 44959 | P12: 295 | R12: 1,12,16 | S12: 44895 | T12: 45381 | U12: 45473 | V12: 45565 | W12: 45656 | X12: 45656 | Y12: 61057630 | Z12: ДПГ-23-01-029/129 | AB12: Баркинхоев А.М. | AC12: Алимжанова Д.К. | AD12: 75 | AE12: 1 | AG12: 301 | AI12: г. Астана | AJ12: г. Астана | AK12: =CONCATENATE(YEAR(O12)," год") -> 2023 год | AL12: =CONCATENATE(YEAR(O12)," год") -> 2023 год | AM12: 1
A13: 7 | B13: МЖК Asyl Tas | C13: 44978 | D13: г. Шымкент | E13: ТОО "ВВД-Құрылыс" | F13: 060240025805 | G13: ТОО "CRYSTAL SHYMKENT" | H13: 221140027032 | I13: 2757296296 | J13: 9446.26 | K13: 6432.11 | L13: 1306.1 | M13: 291.9 | N13: 421.9 | O13: 44991 | P13: 103 | R13: 5 | S13: 44903 | T13: 45268 | U13: 45359 | V13: 45451 | W13: 45543 | X13: 08.09.2024 Гарантийный случай | Y13: 24124259 | Z13: ДПГ-23-13-055/132 | AB13: Исмаков А.С. | AC13: Жакыпбеков А.Д. | AD13: 85 | AE13: 3 | AG13: 327 | AI13: г. Шымкент | AJ13: г. Шымкент | AK13: =CONCATENATE(YEAR(O13)," год") -> 2023 год | AL13: =CONCATENATE(YEAR(O13)," год") -> 2023 год | AM13: 1
A14: - | B14: Увеличение стоимости МЖК Kerim | C14: 44973 | D14: г. Астана | E14: ТОО "Актау Коркем Курылыс" | F14: 180440021488 | G14: ТОО "ОрдаСтройИнжиниринг" | H14: 110940007041 | I14: 2441858042 | J14: 0 | M14: - | N14: - | O14: 45000 | P14: 0 | R14: 0 | S14: 44636 | T14: 45185 | U14: 45276 | V14: 45367 | X14: 16.03.2024 Акт на регистрации | Y14: 24418580 | Z14: ДС № 2 к ДПГ-22-01-054/117 | AB14: Баркинхоев А.М. | AC14: Алимжанова Д.К. | AD14: 93 | AE14: 2 | AG14: 340 | AJ14: г. Астана | AL14: =CONCATENATE(YEAR(O14)," год") -> 2023 год
A15: 8 | B15: МЖК Аман пятно 7 | C15: 44992 | D15: г. Астана | E15: ТОО "BAZIS-A Corp." | F15: 960340000376 | G15: ТОО "Орынбор 2017" | H15: 160340010168 | I15: 2596718603 | J15: 10209.6 | K15: 7356.9 | L15: 489.7 | M15: 254.341 | N15: 390 | O15: 45016 | P15: 135 | R15: 16 | S15: 44853 | T15: 45370 | U15: до 19.03.2025 консервация проекта | X15: 45735 | Y15: 24521857 | Z15: ДПГ-23-01-001/134 | AB15: Баркинхоев А.М. | AC15: Алимжанова Д.К. | AD15: 85 | AE15: 0 | AG15: 322 | AI15: г. Астана | AJ15: г. Астана | AK15: =CONCATENATE(YEAR(O15)," год") -> 2023 год | AL15: =CONCATENATE(YEAR(O15)," год") -> 2023 год | AM15: 1
A16: 9 | B16: МЖК Apartex Burabay | C16: 45023 | D16: Акмолинская область, г. Щучинск | E16: ТОО "Биik Шаңырақ" | F16: 140740007872 | G16: ТОО "Apartex Burabay" | H16: 140340019900 | I16: 380442507 | J16: 2497.15 | K16: 1965.55 | M16: 152.351 | N16: 271.833 | O16: 45044 | P16: 60 | R16: 5 | S16: 44974 | T16: 45155 | U16: 45247 | V16: 45339 | W16: 17.05.2024/ продлен по ЧС до 28.06.2024 | X16: 27.06.2024 Акт на регистрации | Y16: 3406925 | Z16: ДПГ-23-03-034/137 | AB16: Кенесов М.Г. | AC16: Арыстанбекова А.И. | AD16: 89 | AE16: 3 | AG16: 354 | AI16: Акмолинская область | AJ16: Акмолинская область | AK16: =CONCATENATE(YEAR(O16)," год") -> 2023 год | AL16: =CONCATENATE(YEAR(O16)," год") -> 2023 год | AM16: 1
A17: 10 | B17: МЖК Sezim Qala, очередь 13 | C17: 45051 | D17: г. Астана | E17: ТОО "Nova City Development" | F17: 110540015593 | G17: ТОО "Ғимарат НС" | H17: 130740010573 | I17: 6608817195 | J17: 20565.12 | K17: 16685.12 | M17: 321.361 | N17: 440 | O17: 45077 | P17: 278 | R17: 20 | S17: 44981 | T17: 45620 | X17: 02.10.2024 Акт на регистрации | Y17: 66088172 | Z17: ДПГ-23-01-008/141 | AB17: Баркинхоев А.М. | AC17: Алимжанова Д.К. | AD17: 92 | AE17: 0 | AF17: 0 | AG17: 368 | AI17: г. Астана | AJ17: г. Астана | AK17: =CONCATENATE(YEAR(O17)," год") -> 2023 год | AL17: =CONCATENATE(YEAR(O17)," год") -> 2023 год | AM17: 1
A18: 11 | B18: МЖК Столичный -2, блок 4 | C18: 45104 | D18: г. Астана | E18: ТОО "MERIDIAN stroy LTD." | F18: 070740007004 | G18: ТОО "EGREGOR OF FINANCE SH.R." | H18: 180540002396 | I18: 3834322743 | J18: 12795 | K18: 9388.5 | L18: 526.5 | M18: 299.674 | N18: 440 | O18: 45126 | P18: 161 | R18: 24 | S18: 45027 | T18: 45454 | U18: 45546 | X18: 13.08.2024 Акт на регистрации | Y18: 33018568 | Z18: ДПГ-23-01-047/146 | AB18: Баркинхоев А.М. | AC18: Алимжанова Д.К. | AD18: 66 | AE18: 1 | AF18: 0 | AG18: 362 | AI18: г. Астана | AJ18: г. Астана | AK18: =CONCATENATE(YEAR(O18)," год") -> 2023 год | AL18: =CONCATENATE(YEAR(O18)," год") -> 2023 год | AM18: 1
A19: 12 | B19: МЖК "PARASAT II, 1 очередь (п.1-6)" | C19: 45111 | D19: г. Алматы | E19: ТОО "SHEBERGOOD" | F19: 070240017648 | G19: ТОО "PARASAT II" | H19: 210740017974 | I19: 11378893818 | J19: 26579 | K19: 20305.2 | L19: 1218.3 | M19: 428.115 | N19: 563.661 | O19: 45127 | P19: 381 | R19: 9 | S19: 45014 | T19: 45564 | U19: 45655 | X19: 45655 | Y19: 100323683 | Z19: ДПГ-23-02-064/147 | AB19: Кожухова Д.Б. | AC19: Смайлова Д.Н. | AD19: 63 | AE19: 0 | AF19: 0 | AG19: 393 | AI19: г. Алматы | AJ19: г. Алматы | AK19: =CONCATENATE(YEAR(O19)," год") -> 2023 год | AL19: =CONCATENATE(YEAR(O19)," год") -> 2023 год | AM19: 1
A20: 13 | B20: МЖК Лесная поляна, 12 очередь, 46Д | C20: 45125 | D20: Акмолинская область, г. Косшы | E20: ТОО "Марапат 2011" | F20: 111140016064 | G20: ТОО "LP City" | H20: 211040012059 | I20: 2953550085 | J20: 14028.4 | K20: 9219.4 | L20: 1971.1 | M20: 263.933 | N20: 289.371 | O20: 45156 | P20: 210 | R20: 5 | S20: 45005 | T20: 45588 | X20: 27.09.2024 акт на регистрации | Y20: 22334217 | Z20: ДПГ-23-03-049/148 | AB20: Кенесов М.Г. | AC20: Арыстанбекова А.И. | AD20: 86 | AE20: 0 | AF20: 1 | AG20: 401 | AI20: Акмолинская область | AJ20: Акмолинская область | AK20: =CONCATENATE(YEAR(O20)," год") -> 2023 год | AL20: =CONCATENATE(YEAR(O20)," год") -> 2023 год | AM20: 1
A21: 14 | B21: МЖК Маяк | C21: 45139 | D21: Алматинская область, г.Конаев | E21: ТОО "КОРПОРАЦИЯ "АСТАНА-СТРОЙИНВЕСТ" | F21: 000740002447 | G21: ТОО "MDI CONSTRUCTION" | H21: 190440002700 | I21: 4916104675 | J21: 15148.34 | K21: 13381.08 | L21: 574.5 | M21: 324.531 | N21: 450 | O21: 45156 | P21: 216 | R21: 4 | S21: 45112 | T21: 45356 | U21: 45448 | V21: 45540 | X21: 45540 | Y21: 44559067 | Z21: ДПГ-23-05-012/149 | AB21: Кожухова Д.Б. | AC21: Смайлова Д.Н. | AD21: 79 | AE21: 1 | AF21: 1 | AG21: 388 | AI21: Алматинская область | AJ21: Алматинская область | AK21: =CONCATENATE(YEAR(O21)," год") -> 2023 год | AL21: =CONCATENATE(YEAR(O21)," год") -> 2023 год | AM21: 1
A22: 15 | B22: МЖК New City 1-2 (МЖК Ferrum City) | C22: 45153 | D22: г. Астана | E22: ТОО "Ferrum Co." | F22: 091040005188 | G22: ТОО "New City1-2" | H22: 210740017161 | I22: 4002124719 | J22: 14200.88 | K22: 8791.97 | L22: 1122.58 | M22: 403.662 | N22: 458.76 | O22: 45177 | P22: 117 | R22: 9.18 | S22: 45083 | T22: 45632 | X22: 45632 | Y22: 32891558 | Z22: ДПГ-23-01-066/152 | AB22: Баркинхоев А.М. | AC22: Алимжанова Д.К. | AD22: 65 | AE22: 0 | AF22: 1 | AG22: 406 | AI22: г. Астана | AJ22: г. Астана | AK22: =CONCATENATE(YEAR(O22)," год") -> 2023 год | AL22: =CONCATENATE(YEAR(O22)," год") -> 2023 год | AM22: 1
A23: 16 | B23: МЖК Лесная поляна, 12 очередь, 49Д | C23: 45181 | D23: Акмолинская область, г. Косшы | E23: ТОО "Марапат 2011" | F23: 111140016064 | G23: ТОО "LP City" | H23: 211040012059 | I23: 2623982344 | J23: 11041.2 | K23: 7287.6 | L23: 1507.2 | M23: 237.654 | N23: 314.971 | O23: 45197 | P23: 140 | R23: 5 | S23: 45142 | T23: 45630 | X23: 45630 | Y23: 15415734 | Z23: доп.согл. №1 к ДПГ-23-03-049/148 от 18.08.23г. | AB23: Кенесов М.Г. | AC23: Арыстанбекова А.И. | AD23: 81 | AE23: 0 | AF23: 1 | AG23: 419 | AI23: Акмолинская область | AJ23: Акмолинская область | AK23: =CONCATENATE(YEAR(O23)," год") -> 2023 год | AL23: =CONCATENATE(YEAR(O23)," год") -> 2023 год | AM23: 1
A24: 17 | B24: МЖК Жаным, 1 пусковой комплекс (МЖК V Club) | C24: 45188 | D24: г. Усть-Каменогорск | E24: ТОО "Biryuza Construction» | F24: 040440036894 | G24: ТОО "УК Шанырак Строй" | H24: 230340036850 | I24: 1802298543 | J24: 6888.13 | K24: 5523.29 | M24: 261.652 | N24: 376.667 | O24: 45210 | P24: 63 | R24: 9 | S24: 45159 | T24: 45556 | U24: 45647 | X24: 45647 | Y24: 14849026 | Z24: ДПГ-23-16-068/155 | AB24: Баркинхоев А.М. | AC24: Алимжанова Д.К. | AD24: 66 | AE24: 0 | AF24: 1 | AG24: 426 | AI24: г. Усть-Каменогорск | AJ24: г. Усть-Каменогорск | AK24: =CONCATENATE(YEAR(O24)," год") -> 2023 год | AL24: =CONCATENATE(YEAR(O24)," год") -> 2023 год | AM24: 1
A25: 18 | B25: МЖК Лесная поляна, 12 очередь, 48 Д | C25: 45188 | D25: Акмолинская область, г. Косшы | E25: ТОО "Марапат 2011" | F25: 111140016064 | G25: ТОО "LP City" | H25: 211040012059 | I25: 1635711572 | J25: 6384.3 | K25: 4479.5 | L25: 975.9 | M25: 256.208 | N25: 309.409 | O25: 45217 | P25: 110 | R25: 5 | S25: 45156 | T25: 45522 | U25: 45614 | X25: 20.09.2024 акт на регистрации | Y25: 9595485 | Z25: доп.согл. №2 к ДПГ-23-03-049/148 от 18.08.2023 | AB25: Кенесов М.Г. | AC25: Арыстанбекова А.И. | AD25: 81 | AE25: 1 | AF25: 1 | AG25: 422 | AI25: Акмолинская область | AJ25: Акмолинская область | AK25: =CONCATENATE(YEAR(O25)," год") -> 2023 год | AL25: =CONCATENATE(YEAR(O25)," год") -> 2023 год | AM25: 1
A26: 19 | B26: МЖК Салем | C26: 45188 | D26: Акмолинская область, г.Кокшетау | E26: ТОО "Биik Шаңырақ" | F26: 140740007872 | G26: ТОО "M-Group Asia" | H26: 220240012372 | I26: 1088278078 | J26: 5851.02 | K26: 3760.1 | M26: 289.428 | N26: 314.459 | O26: 45217 | P26: 119 | R26: 12 | S26: 45131 | T26: 45436 | U26: продлен по ЧС до 19.07.2024 | X26: 45492 | Y26: 9145815 | Z26: ДПГ-23-03-034/154 | AB26: Кенесов М.Г. | AC26: Арыстанбекова А.И. | AD26: 77 | AE26: 0 | AF26: 1 | AG26: 421 | AI26: Акмолинская область | AJ26: Акмолинская область | AK26: =CONCATENATE(YEAR(O26)," год") -> 2023 год | AL26: =CONCATENATE(YEAR(O26)," год") -> 2023 год | AM26: 1
A27: 20 | B27: МЖК Гранд Виктория 2 | C27: 45237 | D27: г. Астана | E27: ТОО "Бағыстан" | F27: 161140023096 | G27: ТОО "BUILDINGPLUS" | H27: 180840024962 | I27: 9176506252 | J27: 28301.1 | K27: 18053.2 | L27: 1895.59 | M27: 324.245 | N27: 460.00315 | O27: 45251 | P27: 264 | R27: 1, 9 | S27: 45191 | T27: 45465 | U27: 45557 | V27: 45648 | X27: 45648 | Y27: 77965812 | Z27: ДПГ-23-01-069/158 | AB27: Баркинхоев А.М. | AC27: Алимжанова Д.К. | AD27: 78 | AE27: 1 | AF27: 1 | AG27: 445 | AH27: да | AI27: г. Астана | AJ27: г. Астана | AK27: =CONCATENATE(YEAR(O27)," год") -> 2023 год | AL27: =CONCATENATE(YEAR(O27)," год") -> 2023 год | AM27: 1
A28: 21 | B28: МЖК Otbasy 1 очередь | C28: 45267 | D28: г. Шымкент | E28: ТОО "Kanfar Building" | F28: 060340004172 | G28: ТОО "Otbasy Satu" | H28: 230240002119 | I28: 6804685307 | J28: 17783.17 | K28: 10454 | L28: 1386.47 | M28: 382.647 | N28: 440 | O28: 45288 | P28: 192 | R28: 9 | S28: 45198 | T28: 45533 | X28: 28.08.2024 акт на регистрации | Y28: 61009602 | Z28: ДПГ-23-17-050/159 | AB28: Исмаков А.С. | AC28: Жакыпбеков А.Д. | AD28: 73 | AE28: 0 | AF28: 1 | AG28: 455 | AH28: да | AI28: г. Шымкент | AJ28: г. Шымкент | AK28: =CONCATENATE(YEAR(O28)," год") -> 2023 год | AL28: =CONCATENATE(YEAR(O28)," год") -> 2023 год | AM28: 1
A29: 22 | B29: МЖК Бағыстан 1, 5 оч.позиция 2,4 | C29: 45272 | D29: г. Астана | E29: ТОО "Бағыстан" | F29: 161140023096 | G29: ТОО "NEW LINE PROJECT" | H29: 180240031389 | I29: 1.5986085e+10 | J29: 110897.01 | K29: 48140.85 | L29: 2545.6 | M29: 144.153 | N29: 374.57 | O29: 45288 | P29: 793 | R29: 7,9,12,15,17 | S29: 45191 | T29: 45891 | X29: 45891 | Y29: 1.5578159e+08 | Z29: ДПГ-23-01-069/160 | AB29: Баркинхоев А.М. | AC29: Алимжанова Д.К. | AD29: 83 | AE29: 0 | AF29: 1 | AG29: 450 | AH29: да | AI29: г. Астана | AJ29: г. Астана | AK29: =CONCATENATE(YEAR(O29)," год") -> 2023 год | AL29: =CONCATENATE(YEAR(O29)," год") -> 2023 год | AM29: 1
A30: 23 | B30: МЖК NOHO | C30: 45281 | D30: г. Астана | E30: ТОО "BAZIS-A Corp." | F30: 960340000376 | G30: ТОО "SOVICO GROUP" | H30: 180240017561 | I30: 10030993319 | J30: 54345.6 | K30: 32867.74 | L30: 3319.17 | M30: 277.199 | N30: 350 | O30: 45308 | P30: 423 | R30: 9,12,14,16 | S30: 45127 | T30: 45858 | X30: 45858 | Y30: 99060352 | Z30: ДПГ-24-01-001/162 | AB30: Баркинхоев А.М. | AC30: Алимжанова Д.К. | AD30: 91 | AE30: 0 | AF30: 2 | AG30: 444 | AI30: г. Астана | AJ30: г. Астана | AK30: =CONCATENATE(YEAR(O30)," год") -> 2024 год | AL30: =CONCATENATE(YEAR(O30)," год") -> 2024 год | AM30: 1
A31: 24 | B31: МЖК Salzburg, блок 3 | C31: 45274 | D31: г. Астана | E31: ТОО "BAZIS-A Corp." | F31: 960340000376 | G31: ТОО "Euro City-2" | H31: 190440041424 | I31: 1544370732 | J31: 7198.2 | K31: 4879.2 | L31: 716.4 | M31: 214.55 | N31: 350 | O31: 45309 | P31: 54 | R31: 8 | S31: 45175 | T31: 45541 | U31: 45632 | X31: 45632 | Y31: 14909071 | Z31: ДПГ-23-01-001/161 | AB31: Баркинхоев А.М. | AC31: Алимжанова Д.К. | AD31: 91 | AE31: 0 | AF31: 2 | AG31: 442 | AI31: г. Астана | AJ31: г. Астана | AK31: =CONCATENATE(YEAR(O31)," год") -> 2024 год | AL31: =CONCATENATE(YEAR(O31)," год") -> 2024 год | AM31: 1
A32: 25 | B32: МЖК Salzburg, блок 4 | C32: 45274 | D32: г. Астана | E32: ТОО "BAZIS-A Corp." | F32: 960340000376 | G32: ТОО "Euro City-2" | H32: 190440041424 | I32: 1372954735 | J32: 6094.3 | K32: 4080.6 | L32: 381.6 | M32: 225.285 | N32: 360 | O32: 45309 | P32: 40 | R32: 8 | S32: 45175 | T32: 45541 | U32: 45632 | X32: 45632 | Y32: 13001244 | Z32: ДПГ-23-01-001/161 | AB32: Баркинхоев А.М. | AC32: Алимжанова Д.К. | AD32: 91 | AE32: 0 | AF32: 2 | AG32: 443 | AI32: г. Астана | AJ32: г. Астана | AK32: =CONCATENATE(YEAR(O32)," год") -> 2024 год | AL32: =CONCATENATE(YEAR(O32)," год") -> 2024 год | AM32: 1
A33: 26 | B33: МЖК Modern City 2 | C33: 45300 | D33: г. Шымкент | E33: ТОО "Оңтүстік құрылыс Сервис" | F33: 010340004024 | G33: ТОО "OKS-Shymcity" | H33: 201140025012 | I33: 8967320951 | J33: 23220.52 | K33: 18073.93 | L33: 917.85 | M33: 386.181 | N33: 450.9 | O33: 45324 | P33: 271 | R33: 9 | S33: 45219 | T33: 45646 | X33: 45646 | Y33: 71541895 | Z33: доп.согл. №4 к ДПГ-22-13-004/106 от 11.02.2022 | AB33: Исмаков А.С. | AC33: Жакыпбеков А.Д. | AD33: 71 | AE33: 0 | AF33: 1 | AG33: 459 | AI33: г. Шымкент | AJ33: г. Шымкент | AK33: =CONCATENATE(YEAR(O33)," год") -> 2024 год | AL33: =CONCATENATE(YEAR(O33)," год") -> 2024 год | AM33: 1
A34: 27 | B34: МЖК Байтерек | C34: 45317 | D34: г. Уральск | E34: ТОО "Караванный путь" | F34: 030840007596 | G34: ТОО "Уркер Строй" | H34: 220340033735 | I34: 1886723001 | J34: 10334 | K34: 7497 | M34: 182.574 | N34: 280 | O34: 45348 | P34: 150 | R34: 5 | S34: 45352 | T34: 45566 | X34: 45566 | Y34: 18867230 | Z34: ДПГ-24-07-006/163 | AB34: Аяпова Г.Н. | AC34: Жусанова Т.А. | AD34: 73 | AE34: 0 | AF34: 3 | AG34: 456 | AI34: г. Уральск | AJ34: г. Уральск | AK34: =CONCATENATE(YEAR(O34)," год") -> 2024 год | AL34: =CONCATENATE(YEAR(O34)," год") -> 2024 год | AM34: 1
A35: 28 | B35: МЖК Английский квартал, г.Атырау | C35: 45337 | D35: г. Атырау | E35: ТОО "I BIGMA KZ" | F35: 080240012629 | G35: ТОО "КАСПИЙ-ЭКСПО" | H35: 080840016029 | I35: 3595425509 | J35: 25056.9 | K35: 18161.2 | L35: 2335.2 | M35: 143 | N35: 312 | O35: 45365 | P35: 240 | R35: 9 | S35: 45243 | T35: 45670 | X35: 45670 | Y35: 32350689 | Z35: ДПГ-24-06-070/164 | AB35: Аяпова Г.Н. | AC35: Жусанова Т.А. | AD35: 68 | AE35: 0 | AF35: 1 | AG35: 469 | AI35: г. Атырау | AJ35: г. Атырау | AK35: =CONCATENATE(YEAR(O35)," год") -> 2024 год | AL35: =CONCATENATE(YEAR(O35)," год") -> 2024 год | AM35: 1
A36: 29 | B36: МЖК Атамура, 2 очередь | C36: 45337 | D36: г. Астана | E36: ТОО "Жетісу ЖҚ" | F36: 031240005283 | G36: ТОО "Горде" | H36: 120540000160 | I36: 7672975159 | J36: 19294.2 | K36: 13480 | L36: 1150.8 | M36: 397.682 | N36: 488.649 | O36: 45371 | P36: 296 | R36: 9, 17 | S36: 45327 | T36: 45677 | X36: 45677 | Y36: 64691452 | Z36: доп.согл. №4 от 20.03.24г к ДПГ-22-01-024/116 от 11.08.22г | AB36: Баркинхоев А.М. | AC36: Алимжанова Д.К. | AD36: 65 | AE36: 0 | AF36: 1 | AG36: 473 | AI36: г. Астана | AJ36: г. Астана | AK36: =CONCATENATE(YEAR(O36)," год") -> 2024 год | AL36: =CONCATENATE(YEAR(O36)," год") -> 2024 год | AM36: 1
A37: 30 | B37: МЖК Престиж 3 (дома 5, 6) | C37: 45357 | D37: г. Шымкент | E37: ТОО "Композит-7" | F37: 050640012251 | G37: ТОО "PRESTIGE INVEST" | H37: 220140016321 | I37: 1613184111 | J37: 5712 | K37: 4190.55 | M37: 282 | N37: 433.8 | O37: 45380 | P37: 45 | R37: 5 | S37: 45316 | T37: 45621 | X37: 45621 | Y37: 14439086 | Z37: ДПГ-24-17-046/165 | AB37: Исмаков А.С. | AC37: Жакыпбеков А.Д. | AD37: 82 | AE37: 0 | AF37: 1 | AG37: 478 | AI37: г. Шымкент | AJ37: г. Шымкент | AK37: =CONCATENATE(YEAR(O37)," год") -> 2024 год | AL37: =CONCATENATE(YEAR(O37)," год") -> 2024 год | AM37: 1
A38: 31 | B38: МЖК Landmark, 3 очередь, пятна 1,3 | C38: 45366 | D38: г. Астана | E38: ТОО "BAZIS-A Corp." | F38: 960340000376 | G38: ТОО "DOSTYK LAND" | H38: 190240034484 | I38: 2815219201 | J38: 13082.17 | K38: 7430.63 | L38: 446.34 | M38: 301 | N38: 440 | O38: 45393 | P38: 75 | R38: 16.1 | S38: 45174 | T38: 45693 | X38: 45693 | Y38: 23678424 | Z38: доп.согл. №9 от 11.04.2024г к ДПГ-20-01-001/037 от28.02.20г | AB38: Баркинхоев А.М. | AC38: Алимжанова Д.К. | AD38: 92 | AE38: 0 | AF38: 1 | AG38: 481 | AI38: г. Астана | AJ38: г. Астана | AK38: =CONCATENATE(YEAR(O38)," год") -> 2024 год | AL38: =CONCATENATE(YEAR(O38)," год") -> 2024 год | AM38: 1
A39: 32 | B39: МЖК Bilim | C39: 45370 | D39: г. Астана | E39: ТОО "STROY OPT" | F39: 131240018048 | G39: ТОО "DAULETTI QALASHYQ" | H39: 170940003812 | I39: 13763471058 | J39: 66064.54 | K39: 42367.37 | L39: 3742.01 | M39: 208.334 | N39: 359 | O39: 45379 | P39: 674 | R39: 9,12,14,18 | S39: 45351 | T39: 45716 | X39: 45716 | Y39: 117673184 | Z39: ДПГ-24-01-044/166 | AB39: Баркинхоев А.М. | AC39: Алимжанова Д.К. | AD39: 85 | AE39: 0 | AF39: 1 | AG39: 484 | AI39: г. Астана | AJ39: г. Астана | AK39: =CONCATENATE(YEAR(O39)," год") -> 2024 год | AL39: =CONCATENATE(YEAR(O39)," год") -> 2024 год | AM39: 1
A40: 33 | B40: МЖК RAAF | C40: 45384 | D40: г. Алматы | E40: ТОО "EXCLUSIVE KURMANGAZY" | F40: 170840003753 | G40: ТОО "Exclusive Star" | H40: 200440003119 | I40: 6933930768 | J40: 31440.78 | K40: 19913.75 | L40: 1970.11 | M40: 220.539 | N40: 674.786 | O40: 45394 | P40: 261 | R40: 8.9 | S40: 45273 | T40: 45974 | X40: 45974 | Y40: 69339308 | Z40: ДПГ-24-02-071/167 | AB40: Кожухова Д.Б. | AC40: Смайлова Д.Н. | AD40: 64 | AE40: 0 | AF40: 1 | AG40: 476 | AI40: г. Алматы | AJ40: г. Алматы | AK40: =CONCATENATE(YEAR(O40)," год") -> 2024 год | AL40: =CONCATENATE(YEAR(O40)," год") -> 2024 год | AM40: 1
A41: 34 | B41: МЖК в мкр.Береке №18 | C41: 45391 | D41: г. Костанай | E41: ТОО "БК-СТРОЙ" | F41: 031040001233 | G41: ТОО "БК-Береке 18" | H41: 240140030559 | I41: 2341382653 | J41: 10974.61 | K41: 6795.68 | M41: 213.345 | N41: 360 | O41: 45418 | P41: 120 | R41: 5 | S41: 45414 | T41: 45718 | X41: 45718 | Y41: 23413827 | Z41: ДПГ-24-10-048|170 | AB41: Кенесов М.Г. | AC41: Арыстанбекова А.И. | AD41: 96 | AE41: 0 | AF41: 1 | AG41: 485 | AI41: г. Костанай | AJ41: г. Костанай | AK41: =CONCATENATE(YEAR(O41)," год") -> 2024 год | AL41: =CONCATENATE(YEAR(O41)," год") -> 2024 год | AM41: 1
...

Sheet Завершенные
B1: Завершенные проекты
A3: № | B3: Наименование Проекта | C3: Дата решение Правления/СД | D3: Регион | E3: Застройщик | F3: БИН Застройщика | G3: Уполномоченная компания | H3: БИН Уполномоченной компании | I3: Стоимость, тенге | J3: Площадь, кв.м по Проекту | K3: Площадь квартир, кв.м по Проекту | L3: Площадь коммерческих помещений, кв.м. | M3: Себестоимость тыс.тенге/1 м2 | N3: Цена реал. тыс.тенге/1 м2 | O3: Дата заключения договора о предоставлении гарантии | P3: Количество квартир по Проекту | Q3: Количество квартир по факту (после ввода)* | R3: Этажность | S3: Дата начала строительства | T3: Дата завершения | U3: Дата пролонгации 1 | V3: Дата пролонгации 2 | W3: Дата пролонгации 3 | X3: Дата завершения 2/Дата по АПОЭ | Y3: Гарантийный взнос, тенге | Z3: № ДПГ | AA3: Итоговая стоимость с учетом снижения обязательств | AB3: Исполнитель | AC3: Куратор | AD3: Балл Застройщика | AE3: Кол-во продлении | AF3: Кол-во модерации | AG3: Номер в SB | AH3: Наличие "Зеленого сертификатв" | AI3: Регион Кол-во | AJ3: Регион Ст-ть | AK3: Год Кол-во | AL3: Год Ст-ть | AM3: Статус
A4: 1 | B4: ЖК "Миллениум парк", пятно 2, 14 блок | C4: 42870 | D4: г. Астана | E4: ТОО "BAZIS-A Corp." | F4: 960340000376 | G4: ТОО "Аллея тысячелетия-2" | H4: 160340010693 | I4: 2516814000 | J4: 14000 | O4: 42873 | P4: 178 | Q4: 178 | R4: 24 | S4: 42513 | T4: 43519 | X4: 43154 | Y4: 50336280 | Z4: ДПГ-17-01-001-02/001 | AD4: 100 | AI4: г. Астана | AJ4: г. Астана | AK4: =CONCATENATE(YEAR(O4)," год") -> 2017 год | AL4: =CONCATENATE(YEAR(O4)," год") -> 2017 год | AM4: =1 -> 1
A5: 2 | B5: ЖК "Легенда", 1 очередь (пятна 1-6) | C5: 42968 | D5: г. Алматы | E5: ТОО "BAZIS-A Corp." | F5: 960340000376 | G5: ТОО "KAT-Construction" | H5: 160640015734 | I5: 6866978080 | J5: 35371.3 | O5: 43000 | P5: 400 | Q5: 396 | R5: 14-16 | S5: 42895 | T5: 43474 | X5: 43454 | Y5: 137339562 | Z5: ДПГ-17-02-001/002 | AD5: 100 | AI5: г. Алматы | AJ5: г. Алматы | AK5: =CONCATENATE(YEAR(O5)," год") -> 2017 год | AL5: =CONCATENATE(YEAR(O5)," год") -> 2017 год | AM5: =1 -> 1
A6: 3 | B6: ЖК Алтын Ұя | C6: 43090 | D6: г. Астана | E6: ТОО "Comfort Development KZ" | F6: 210940032945 | G6: ТОО "AKAN Engineering" | H6: 140540020406 | I6: 1576632159 | J6: 13084 | O6: 43122 | P6: 148 | Q6: 167 | R6: 10 | S6: 42765 | T6: 43339 | X6: 43339 | Y6: 18956603 | Z6: ДПГ-17-01-002/003 | AD6: 67 | AI6: г. Астана | AJ6: г. Астана | AK6: =CONCATENATE(YEAR(O6)," год") -> 2018 год | AL6: =CONCATENATE(YEAR(O6)," год") -> 2018 год | AM6: =1 -> 1
A7: 4 | B7: МЖК Легенда, 2 очередь, ПАРКИНГ | C7: 43132 | D7: г. Алматы | E7: ТОО "BAZIS-A Corp." | F7: 960340000376 | G7: ТОО "KAT-Construction" | H7: 160640015734 | I7: 1348115202 | J7: 8303.1 | O7: 43146 | P7: 233 | Q7: 233 | R7: 1 | S7: 43005 | T7: 43461 | X7: 43454 | Y7: 24756844 | Z7: доп.согл. №1 к ДПГ-17-02-001/002 | AD7: 100 | AI7: г. Алматы | AJ7: г. Алматы | AK7: =CONCATENATE(YEAR(O7)," год") -> 2018 год | AL7: =CONCATENATE(YEAR(O7)," год") -> 2018 год | AM7: =1 -> 1
A8: 5 | B8: МЖК Alma City, 1 очередь | C8: 43193 | D8: г. Алматы | E8: ТОО "Qazaq Stroy" | F8: 050540016141 | G8: ТОО "Елимай-Invest" | H8: 160640016168 | I8: 1543068030 | J8: 26577.5 | O8: 43214 | P8: 300 | Q8: 360 | R8: 5 | S8: 43161 | T8: 43526 | X8: 43482 | Y8: 28414166 | Z8: ДПГ-18-02-005/006 | AD8: 91 | AI8: г. Алматы | AJ8: г. Алматы | AK8: =CONCATENATE(YEAR(O8)," год") -> 2018 год | AL8: =CONCATENATE(YEAR(O8)," год") -> 2018 год | AM8: =1 -> 1
A9: 6 | B9: ЖК на Гагарина 1 | C9: 43206 | D9: г. Уральск | E9: ТОО "Караванный путь" | F9: 030840007596 | G9: ТОО "Stroy Baiterek" | H9: 170740034528 | I9: 1279348120 | J9: 7546.7 | O9: 43218 | P9: 126 | Q9: 126 | R9: 9 | S9: 42964 | T9: 43512 | X9: 43477 | Y9: 15796882 | Z9: ДПГ-18-07-006/007 | AD9: 64 | AI9: г. Уральск | AJ9: г. Уральск | AK9: =CONCATENATE(YEAR(O9)," год") -> 2018 год | AL9: =CONCATENATE(YEAR(O9)," год") -> 2018 год | AM9: =1 -> 1
A10: 7 | B10: МЖК Alma City, 2 очередь | C10: 43325 | D10: г. Алматы | E10: ТОО "Qazaq Stroy" | F10: 050540016141 | G10: ТОО "Елимай-Invest" | H10: 160640016168 | I10: 1543068032 | J10: 26577.5 | O10: 43326 | P10: 300 | Q10: 360 | R10: 5 | S10: 43161 | T10: 43526 | X10: 43482 | Y10: 30861361 | Z10: доп.согл. №1 к ДПГ-18-02-005/006 | AD10: 90 | AI10: г. Алматы | AJ10: г. Алматы | AK10: =CONCATENATE(YEAR(O10)," год") -> 2018 год | AL10: =CONCATENATE(YEAR(O10)," год") -> 2018 год | AM10: =1 -> 1
A11: 8 | B11: МЖК Легенда, 3 очередь, пятна 7, 8, | C11: 43159 | D11: г. Алматы | E11: ТОО "BAZIS-A Corp." | F11: 960340000376 | G11: ТОО "KAT-Construction" | H11: 160640015734 | I11: 2198326780 | J11: 12592.6 | O11: 43175 | P11: 134 | Q11: 134 | R11: 14-15 | S11: 43116 | T11: 43540 | U11: 43632 | X11: 43633 | Y11: 43145556 | Z11: доп.согл. №2 к ДПГ-17-02-001/002 | AD11: 100 | AI11: г. Алматы | AJ11: г. Алматы | AK11: =CONCATENATE(YEAR(O11)," год") -> 2018 год | AL11: =CONCATENATE(YEAR(O11)," год") -> 2018 год | AM11: =1 -> 1
A12: 9 | B12: ЖК SUNRISE | C12: 43325 | D12: г. Астана | E12: ТОО "Милан-Астана" | F12: 110540015593 | G12: ТОО "Тенгри Хаус Астана" | H12: 130340016121 | I12: 7519312044 | J12: 29141.3 | O12: 43341 | P12: 458 | Q12: 569 | R12: 8-9 | S12: 43230 | T12: 43718 | X12: 43703 | Y12: 141232414 | Z12: доп.согл. №1 к ДПГ-18-01-008/009 | AD12: 78 | AI12: г. Астана | AJ12: г. Астана | AK12: =CONCATENATE(YEAR(O12)," год") -> 2018 год | AL12: =CONCATENATE(YEAR(O12)," год") -> 2018 год | AM12: =1 -> 1
A13: 10 | B13: ЖК Nova City | C13: 43390 | D13: г. Астана | E13: ТОО "Милан-Астана" | F13: 110540015593 | G13: ТОО "Камал Центр Астана" | H13: 170540018975 | I13: 6690458969 | J13: 28555.6 | O13: 43398 | P13: 467 | Q13: 467 | R13: 9 | S13: 43296 | T13: 43799 | U13: 43799 | X13: 43784 | Y13: 127426511 | Z13: ДПГ-18-01-008/011 | AD13: 78 | AI13: г. Астана | AJ13: г. Астана | AK13: =CONCATENATE(YEAR(O13)," год") -> 2018 год | AL13: =CONCATENATE(YEAR(O13)," год") -> 2018 год | AM13: =1 -> 1
A14: 11 | B14: ЖК Alma City-2 | C14: 43454 | D14: г. Алматы | E14: ТОО "Qazaq Stroy" | F14: 050540016141 | G14: ТОО "Нұр City Investment" | H14: 181140015247 | I14: 7891739810 | J14: 66742.5 | O14: 43458 | P14: 984 | Q14: 1059 | R14: 9 | S14: 43431 | T14: 43795 | X14: 43788 | Y14: 141881753 | Z14: ДПГ-18-02-005/012 | AD14: 90 | AI14: г. Алматы | AJ14: г. Алматы | AK14: =CONCATENATE(YEAR(O14)," год") -> 2018 год | AL14: =CONCATENATE(YEAR(O14)," год") -> 2018 год | AM14: =1 -> 1
A15: 12 | B15: ЖК Биік Шаңырақ | C15: 43147 | D15: г. Астана | E15: ТОО "НАЕК" | F15: 940140001482 | G15: ТОО "Биік Шаңырақ" | H15: 140740007872 | I15: 2146903508 | J15: 17848.8 | O15: 43162 | P15: 260 | Q15: 276 | R15: 14 | S15: 43160 | T15: 29.02.2019 | U15: 43616 | V15: 43708 | W15: 43890 | X15: 43803 | Y15: 36796147 | Z15: ДПГ-18-01-003/004 | AA15: 1302438420 | AD15: 77 | AI15: г. Астана | AJ15: г. Астана | AK15: =CONCATENATE(YEAR(O15)," год") -> 2018 год | AL15: =CONCATENATE(YEAR(O15)," год") -> 2018 год | AM15: =1 -> 1
A16: 13 | B16: ЖК Бахыт, 1 очередь | C16: 43166 | D16: г. Шымкент | E16: ТОО "Оңтүстік құрылыс Сервис" | F16: 010340004024 | G16: ТОО "Композит-7" | H16: 050640012251 | I16: 2458898850 | J16: 16417.7 | O16: 43194 | P16: 104 | Q16: 104 | R16: 9 | S16: 43160 | T16: 30.04.2019 | U16: 43676 | V16: 43768 | W16: 43860 | X16: 43824 | Y16: 46976477 | Z16: ДПГ-18-13-004/005 | AA16: 2458898850 | AD16: 64 | AI16: г. Шымкент | AJ16: г. Шымкент | AK16: =CONCATENATE(YEAR(O16)," год") -> 2018 год | AL16: =CONCATENATE(YEAR(O16)," год") -> 2018 год | AM16: =1 -> 1
A17: 14 | B17: МЖК Легенда, 5 очередь, пятна 9, 10 | C17: 43313 | D17: г. Алматы | E17: ТОО "BAZIS-A Corp." | F17: 960340000376 | G17: ТОО "KAT-Construction" | H17: 160640015734 | I17: 2502632570 | J17: 12341.8 | O17: 43315 | P17: 94 | Q17: 94 | R17: 14-15 | S17: 43280 | T17: 43859 | X17: 43822 | Y17: 48468231 | Z17: доп.согл. №3 к ДПГ-17-02-001/002 | AD17: 83 | AI17: г. Алматы | AJ17: г. Алматы | AK17: =CONCATENATE(YEAR(O17)," год") -> 2018 год | AL17: =CONCATENATE(YEAR(O17)," год") -> 2018 год | AM17: =1 -> 1
A18: 15 | B18: ЖК Триумфальная арка-2 | C18: 43334 | D18: г. Астана | E18: ТОО "Ңұр Астана Құрылыс" | F18: 060140000846 | G18: ТОО "Мангилик Ел Курылыс" | H18: 170240033531 | I18: 5341879260 | J18: 23920.8 | O18: 43385 | P18: 142 | Q18: 136 | R18: 4,7,9 | S18: 43269 | T18: 44000 | X18: 43977 | Y18: 93091230 | Z18: ДПГ-18-01-009/010 | AD18: 67 | AI18: г. Астана | AJ18: г. Астана | AK18: =CONCATENATE(YEAR(O18)," год") -> 2018 год | AL18: =CONCATENATE(YEAR(O18)," год") -> 2018 год | AM18: =1 -> 1
A19: 16 | B19: МЖК Багыстан, 1-я очередь, 2-очередь, 1, 3 позиции | C19: 43210 | D19: г. Астана | E19: ТОО "Шар Курылыс" | F19: 980740001878 | G19: ТОО "Бағыстан" | H19: 161140023096 | I19: 6541727260 | J19: 41688.6 | O19: 43216 | P19: 324 | Q19: 324 | R19: 5,7,9 | S19: 42921 | T19: 1 позиция - 10.08.2021г.; 3 позиция - 20.10.2021г. | U19: 44134 | V19: 44226 | W19: 44316 | X19: 44489 | Y19: 110832077 | Z19: ДПГ-18-01-007/008 | AD19: 83 | AI19: г. Астана | AJ19: г. Астана | AK19: =CONCATENATE(YEAR(O19)," год") -> 2018 год | AL19: =CONCATENATE(YEAR(O19)," год") -> 2018 год | AM19: =1 -> 1
A20: 17 | B20: МЖК Багыстан, 3-я очередь, 7 позиция | C20: 43286 | D20: г. Астана | E20: ТОО "Шар Курылыс" | F20: 980740001878 | G20: ТОО "Бағыстан" | H20: 161140023096 | I20: 3024902930 | J20: 13362.1 | O20: 43291 | P20: 152 | Q20: 152 | R20: 5,7,9 | S20: 43040 | T20: 20.10.2021 | U20: 44134 | V20: 44226 | W20: 44316 | X20: 44489 | Y20: 56590879 | Z20: доп.согл. №1 к ДПГ-18-01-007/008 | AD20: 83 | AI20: г. Астана | AJ20: г. Астана | AK20: =CONCATENATE(YEAR(O20)," год") -> 2018 год | AL20: =CONCATENATE(YEAR(O20)," год") -> 2018 год | AM20: =1 -> 1
A21: 18 | B21: МЖК Багыстан, 4-я очередь, 11 позиция | C21: 43325 | D21: г. Астана | E21: ТОО "Шар Курылыс" | F21: 980740001878 | G21: ТОО "Бағыстан" | H21: 161140023096 | I21: 3014702450 | J21: 13367.2 | O21: 43336 | P21: 152 | Q21: 152 | R21: 5,7,9 | S21: 43266 | T21: 30.07.2020 | U21: 44134 | V21: 44226 | W21: 44316 | X21: 44489 | Y21: 59088033 | Z21: доп.согл. №3 к ДПГ-18-01-007/008 | AD21: 83 | AI21: г. Астана | AJ21: г. Астана | AK21: =CONCATENATE(YEAR(O21)," год") -> 2018 год | AL21: =CONCATENATE(YEAR(O21)," год") -> 2018 год | AM21: =1 -> 1
A22: 19 | B22: МЖК Sezim Qala, 1 очередь | C22: 43515 | D22: г. Астана | E22: ТОО "Милан-Астана" | F22: 110540015593 | G22: ТОО "Туран Сити" | H22: 170340033307 | I22: 4220953472 | J22: 21443 | O22: 43518 | P22: 277 | Q22: 266 | R22: 9.12 | S22: 43441 | T22: 44142 | X22: 43824 | Y22: 79630069 | Z22: доп.согл. №1 к ДПГ-19-01-008/015 | AD22: 78 | AI22: г. Астана | AJ22: г. Астана | AK22: =CONCATENATE(YEAR(O22)," год") -> 2019 год | AL22: =CONCATENATE(YEAR(O22)," год") -> 2019 год | AM22: =1 -> 1
A23: 20 | B23: ЖК Легенда, 4 очередь (пятна 11, 12) | C23: 43523 | D23: г. Алматы | E23: ТОО "BAZIS-A Corp." | F23: 960340000376 | G23: ТОО "KAT-Construction" | H23: 160640015734 | I23: 1957311630 | J23: 12418.3 | O23: 43543 | P23: 142 | Q23: 142 | R23: 14-15 | S23: 43481 | T23: 43815 | U23: 43906 | X23: 43866 | Y23: 37257013 | Z23: доп.согл. №7 к ДПГ-17-02-001/002 | AD23: 83 | AI23: г. Алматы | AJ23: г. Алматы | AK23: =CONCATENATE(YEAR(O23)," год") -> 2019 год | AL23: =CONCATENATE(YEAR(O23)," год") -> 2019 год | AM23: =1 -> 1
A24: 21 | B24: МЖК Nova City, 19 очередь | C24: 43501 | D24: г. Астана | E24: ТОО "Милан-Астана" | F24: 110540015593 | G24: ТОО "Esil Town" | H24: 181140019271 | I24: 2227028801 | J24: 8855.87 | O24: 43511 | P24: 150 | Q24: 150 | R24: 9 | S24: 43521 | T24: 43946 | X24: 43938 | Y24: 43834498 | Z24: ДПГ-19-01-001/014 | AD24: 78 | AI24: г. Астана | AJ24: г. Астана | AK24: =CONCATENATE(YEAR(O24)," год") -> 2019 год | AL24: =CONCATENATE(YEAR(O24)," год") -> 2019 год | AM24: =1 -> 1
A25: 22 | B25: МЖК Alma City, 3-оч. 1-й пуск.комплекс | C25: 43726 | D25: г. Алматы | E25: ТОО "Qazaq Stroy" | F25: 050540016141 | G25: ТОО "ЫРЫСТЫ 46/2" | H25: 190340022583 | I25: 6600809540 | J25: 64684.2 | O25: 43728 | P25: 1008 | Q25: 1118 | R25: 9 | S25: 43711 | T25: 44257 | X25: 43965 | Y25: 132016191 | Z25: ДПГ-19-02-005/024 | AD25: 81 | AI25: г. Алматы | AJ25: г. Алматы | AK25: =CONCATENATE(YEAR(O25)," год") -> 2019 год | AL25: =CONCATENATE(YEAR(O25)," год") -> 2019 год | AM25: =1 -> 1
A26: 23 | B26: МЖК Амстердам, пятна 4,5,6,7,15.1 | C26: 43482 | D26: г. Астана | E26: ТОО "BAZIS-A Corp." | F26: 960340000376 | G26: ТОО "Amsterdam City" | H26: 180640022394 | I26: 3484165830 | J26: 20748.3 | O26: 43518 | P26: 110 | Q26: 100 | R26: 9-10 | S26: 43357 | T26: 44042 | X26: 44039 | Y26: 68156153 | Z26: ДПГ-19-01-001/013 | AD26: 83 | AI26: г. Астана | AJ26: г. Астана | AK26: =CONCATENATE(YEAR(O26)," год") -> 2019 год | AL26: =CONCATENATE(YEAR(O26)," год") -> 2019 год | AM26: =1 -> 1
A27: 24 | B27: ЖК Nova City 16 очередь | C27: 43634 | D27: г. Астана | E27: ТОО "Милан-Астана" | F27: 110540015593 | G27: ТОО "NC16" | H27: 181240011486 | I27: 4429569296 | J27: 20614.56 | O27: 43647 | P27: 242 | Q27: 242 | R27: 9 | S27: 43588 | T27: 44107 | X27: 44049 | Y27: 86509774 | Z27: ДПГ-19-01-008/016 | AD27: 91 | AI27: г. Астана | AJ27: г. Астана | AK27: =CONCATENATE(YEAR(O27)," год") -> 2019 год | AL27: =CONCATENATE(YEAR(O27)," год") -> 2019 год | AM27: =1 -> 1
A28: 25 | B28: МЖК Парасат, пятно 1,2 | C28: 43783 | D28: г. Алматы | E28: ТОО "SHEBERBUILD" | F28: 070240017648 | G28: ТОО "SHEBERGOOD" | H28: 070240017648 | I28: 1733779999 | J28: 7731.36 | O28: 43796 | P28: 143 | Q28: 143 | R28: 9 | S28: 43760 | T28: 43973 | U28: 44065 | X28: 44064 | Y28: 30929009 | Z28: ДПГ-19-02-013/030 | AD28: 70 | AI28: г. Алматы | AJ28: г. Алматы | AK28: =CONCATENATE(YEAR(O28)," год") -> 2019 год | AL28: =CONCATENATE(YEAR(O28)," год") -> 2019 год | AM28: =1 -> 1
A29: 26 | B29: ЖК Премьера | C29: 43676 | D29: г. Шымкент | E29: ТОО "Оңтүстік құрылыс Сервис" | F29: 010340004024 | G29: ТОО "Dostyq Invest Group" | H29: 190140008530 | I29: 1355115090 | J29: 8903.44 | O29: 43697 | P29: 80 | Q29: 80 | R29: 5 | S29: 43635 | T29: 43970 | U29: 44062 | V29: 44123 | X29: 44068 | Y29: 24228296 | Z29: ДПГ-19-13-004/020 | AD29: 61 | AI29: г. Шымкент | AJ29: г. Шымкент | AK29: =CONCATENATE(YEAR(O29)," год") -> 2019 год | AL29: =CONCATENATE(YEAR(O29)," год") -> 2019 год | AM29: =1 -> 1
A30: 27 | B30: МЖК Nova City, 22 очередь | C30: 43676 | D30: г. Астана | E30: ТОО "Милан-Астана" | F30: 110540015593 | G30: ТОО "NC 22" | H30: 190340029392 | I30: 2453517883 | J30: 8855.87 | O30: 43689 | P30: 150 | Q30: 150 | R30: 9 | S30: 43626 | T30: 44114 | X30: 44112 | Y30: 48045915 | Z30: ДПГ-19-01-008/021 | AD30: 91 | AI30: г. Астана | AJ30: г. Астана | AK30: =CONCATENATE(YEAR(O30)," год") -> 2019 год | AL30: =CONCATENATE(YEAR(O30)," год") -> 2019 год | AM30: =1 -> 1
A31: 28 | B31: ЖК ASQAT | C31: 43665 | D31: г. Астана | E31: ТОО "АсТи-Строй" | F31: 030740000258 | G31: ТОО "ASTI GROUP" | H31: 071240012104 | I31: 3019265161 | J31: 15344.61 | O31: 43677 | P31: 108 | Q31: 108 | R31: 7 | S31: 43633 | T31: 44180 | X31: 44165 | Y31: 50272872 | Z31: ДПГ-19-01-010/018 | AD31: 91 | AI31: г. Астана | AJ31: г. Астана | AK31: =CONCATENATE(YEAR(O31)," год") -> 2019 год | AL31: =CONCATENATE(YEAR(O31)," год") -> 2019 год | AM31: =1 -> 1
A32: 29 | B32: МЖК Argento, пятно 3 | C32: 44081 | D32: г. Астана | E32: ТОО "BAZIS-A Corp." | F32: 960340000376 | G32: ТОО "Строй Билдинг Астана" | H32: 170840009898 | I32: 1136489476 | J32: 7918.13 | O32: 43670 | P32: 85 | Q32: 85 | R32: 18 | S32: 43956 | T32: 44413 | X32: 44398 | Y32: 19307570 | Z32: ДПГ-19-01-001/017 | AD32: 84 | AI32: г. Астана | AJ32: г. Астана | AK32: =CONCATENATE(YEAR(O32)," год") -> 2019 год | AL32: =CONCATENATE(YEAR(O32)," год") -> 2019 год | AM32: =1 -> 1
A33: 30 | B33: МЖК 12 месяцев (на Макатаева), 1-очередь | C33: 43726 | D33: г. Алматы | E33: ТОО "Qazaq Stroy" | F33: 050540016141 | G33: ТОО "Макатаева 127" | H33: 190340022513 | I33: 5130621336 | J33: 36276.5 | O33: 43728 | P33: 432 | Q33: 468 | R33: 12 | S33: 43712 | T33: 44188 | X33: 44188 | Y33: 102612427 | Z33: ДПГ-19-02-005/025 | AD33: 81 | AI33: г. Алматы | AJ33: г. Алматы | AK33: =CONCATENATE(YEAR(O33)," год") -> 2019 год | AL33: =CONCATENATE(YEAR(O33)," год") -> 2019 год | AM33: =1 -> 1
A34: 31 | B34: ЖК Argento пятно 4, Наружные сети | C34: 43643 | D34: г. Астана | E34: ТОО "BAZIS-A Corp." | F34: 960340000376 | G34: ТОО "Строй Билдинг Астана" | H34: 170840009898 | I34: 2161436079 | J34: 12298.3 | O34: 43670 | P34: 100 | Q34: 100 | R34: 21 | S34: 43614 | T34: 44103 | U34: 44194 | X34: 44193 | Y34: 41160642 | Z34: ДПГ-19-01-001/017 | AD34: 78 | AI34: г. Астана | AJ34: г. Астана | AK34: =CONCATENATE(YEAR(O34)," год") -> 2019 год | AL34: =CONCATENATE(YEAR(O34)," год") -> 2019 год | AM34: =1 -> 1
A35: 32 | B35: ЖК Амстердам, пятна 1,2,3 | C35: 43777 | D35: г. Астана | E35: ТОО "BAZIS-A Corp." | F35: 960340000376 | G35: ТОО "Amsterdam City" | H35: 180640022394 | I35: 2176943630 | J35: 11705.1 | O35: 43783 | P35: 82 | Q35: 82 | R35: 9.1 | S35: 43712 | T35: 44193 | X35: 44193 | Y35: 42801333 | Z35: доп.согл. №1 к ДПГ-19-01-001/013 | AD35: 84 | AI35: г. Астана | AJ35: г. Астана | AK35: =CONCATENATE(YEAR(O35)," год") -> 2019 год | AL35: =CONCATENATE(YEAR(O35)," год") -> 2019 год | AM35: =1 -> 1
A36: 33 | B36: ЖК Бахыт, 2 очередь | C36: 43628 | D36: г. Шымкент | E36: ТОО "Оңтүстік құрылыс Сервис" | F36: 010340004024 | G36: ТОО "Композит-7" | H36: 050640012251 | I36: 4853681279 | J36: 27937.7 | O36: 43629 | P36: 168 | Q36: 168 | R36: 9 | S36: 43588 | T36: 44258 | U36: 44350 | X36: 44247 | Y36: 77180276 | Z36: доп.согл. №3 к ДПГ-18-13-004/005 | AA36: 3859013800 | AD36: 61 | AI36: г. Шымкент | AJ36: г. Шымкент | AK36: =CONCATENATE(YEAR(O36)," год") -> 2019 год | AL36: =CONCATENATE(YEAR(O36)," год") -> 2019 год | AM36: =1 -> 1
A37: 34 | B37: ЖК Ак Дидар, пятна 9-13 | C37: 43692 | D37: г. Астана | E37: ТОО "BAZIS-A Corp." | F37: 960340000376 | G37: ТОО "Ак Дидар-2" | H37: 170840012253 | I37: 2415410355 | J37: 16376.6 | O37: 43711 | P37: 276 | Q37: 248 | R37: 9 | S37: 43613 | T37: 44255 | U37: 44344 | X37: 44284 | Y37: 48308207 | Z37: ДПГ-19-01-001/022 | AD37: 78 | AI37: г. Астана | AJ37: г. Астана | AK37: =CONCATENATE(YEAR(O37)," год") -> 2019 год | AL37: =CONCATENATE(YEAR(O37)," год") -> 2019 год | AM37: =1 -> 1
A38: - | B38: Увеличение стоимости ЖК "Ак Дидар", (пятна 9-13) | C38: 43875 | D38: г. Астана | E38: ТОО "BAZIS-A Corp." | F38: 960340000376 | G38: ТОО "Ак Дидар-2" | H38: 170840012253 | I38: 698876654 | J38: 4954 | O38: 43880 | P38: 0 | Q38: 0 | R38: - | S38: 43613 | T38: 44255 | U38: 44344 | X38: 44284 | Y38: 13977533 | Z38: доп.согл. №1 к ДПГ-19-01-001/022 | AD38: 78 | AJ38: г. Астана | AL38: =CONCATENATE(YEAR(O38)," год") -> 2020 год
A39: 35 | B39: ЖК Aspan City | C39: 43665 | D39: Алматинская обл. | E39: ТОО "Exclusive Construction (Эксклюзив Констракшн)" | F39: 051040013647 | G39: ТОО "Aspan City 2" | H39: 181040020140 | I39: 4672680111 | J39: 23277.66 | O39: 43679 | P39: 288 | Q39: 267 | R39: 12 | S39: 43651 | T39: 44058 | U39: 44150 | V39: 44242 | W39: 44331 | X39: 44321 | Y39: 93453602 | Z39: ДПГ-19-02-011/019 | AD39: 73 | AI39: Алматинская область | AJ39: Алматинская область | AK39: =CONCATENATE(YEAR(O39)," год") -> 2019 год | AL39: =CONCATENATE(YEAR(O39)," год") -> 2019 год | AM39: =1 -> 1
A40: 36 | B40: МЖК Бестерек, пятно 1 | C40: 43726 | D40: г. Астана | E40: ТОО "Милан-Астана" | F40: 110540015593 | G40: ТОО "BI-Village Deluxe" | H40: 070340010951 | I40: 6019547133 | J40: 26723.09 | O40: 43735 | P40: 307 | Q40: 307 | R40: 8 | S40: 43662 | T40: 44363 | X40: 44361 | Y40: 119220603 | Z40: ДПГ-19-01-008/023 | AD40: 91 | AI40: г. Астана | AJ40: г. Астана | AK40: =CONCATENATE(YEAR(O40)," год") -> 2019 год | AL40: =CONCATENATE(YEAR(O40)," год") -> 2019 год | AM40: =1 -> 1
A41: 37 | B41: МЖК Sezim Qala, 4 очередь | C41: 43791 | D41: г. Астана | E41: ТОО "Милан-Астана" | F41: 110540015593 | G41: ТОО "Туран Сити" | H41: 170340033307 | I41: 3663548205 | J41: 19815.5 | O41: 43791 | P41: 278 | Q41: 278 | R41: 2, 9, 12 | S41: 43759 | T41: 44393 | X41: 44363 | Y41: 72343291 | Z41: доп.согл. №3 к ДПГ-19-01-008/015 | AD41: 91 | AI41: г. Астана | AJ41: г. Астана | AK41: =CONCATENATE(YEAR(O41)," год") -> 2019 год | AL41: =CONCATENATE(YEAR(O41)," год") -> 2019 год | AM41: =1 -> 1
...

Sheet Лист2
B1: ДЕЙСТВУЮЩИЕ | E1: ЗАВЕРШЕННЫЕ
A2: 1 | B2: № | D2: =B2=E2 -> TRUE | E2: № | F2: =B2=G2 -> TRUE | G2: №
A3: 2 | B3: Наименование Проекта | D3: =B3=E3 -> TRUE | E3: Наименование Проекта | F3: =B3=G3 -> TRUE | G3: Наименование Проекта
A4: 3 | B4: Дата решение Правления/СД | D4: =B4=E4 -> TRUE | E4: Дата решение Правления/СД | F4: =B4=G4 -> TRUE | G4: Дата решение Правления/СД
A5: 4 | B5: Регион | D5: =B5=E5 -> TRUE | E5: Регион | F5: =B5=G5 -> TRUE | G5: Регион
A6: 5 | B6: Застройщик | D6: =B6=E6 -> TRUE | E6: Застройщик | F6: =B6=G6 -> TRUE | G6: Застройщик
A7: 6 | B7: БИН Застройщика | D7: =B7=E7 -> TRUE | E7: БИН Застройщика | F7: =B7=G7 -> TRUE | G7: БИН Застройщика
A8: 7 | B8: Уполномоченная компания | D8: =B8=E8 -> TRUE | E8: Уполномоченная компания | F8: =B8=G8 -> TRUE | G8: Уполномоченная компания
A9: 8 | B9: БИН Уполномоченной компании | D9: =B9=E9 -> TRUE | E9: БИН Уполномоченной компании | F9: =B9=G9 -> TRUE | G9: БИН Уполномоченной компании
A10: 9 | B10: Стоимость, тенге | D10: =B10=E10 -> TRUE | E10: Стоимость, тенге | F10: =B10=G10 -> TRUE | G10: Стоимость, тенге
